Workbook

Sheet Концепция
A6: КОНЦЕПЦИЯ ЗА ИЗГРАЖДАНЕ НА УЧИЛИЩНА STEM СРЕДА
A7: 1 | B7: ДАННИ ЗА КОНТАКТ
A8: 1.1 | B8: Име и фамилия на директора на училището
A9: 1.2 | B9: Телефон за връзка
A10: 1.3 | B10: Име и фамилия на лице за контакт по STEM
A11: 1.4 | B11: Длъжност
A12: 1.5 | B12: Телефон за връзка
A13: 1.6 | B13: E-mail
A14: 2 | B14: ОБЩИ ДАННИ ЗА УЧИЛИЩЕТО
A15: 2.1 | B15: Код на училището по НЕИСПУО:
A16: 2.2 | B16: Код на училището по ЕИК: | F16: =IFERROR(VLOOKUP(F15, Училища!A:W, 23, FALSE()), "")
A17: 2.3 | B17: Наименование на образователна институция: | F17: =IFERROR(VLOOKUP(F15, Училища!A:W, 5, FALSE()), "")
A18: 2.4 | B18: Област: | F18: =IFERROR(VLOOKUP(F15, Училища!A:F, 2, FALSE()), "")
A19: 2.5 | B19: Община : | F19: =IFERROR(VLOOKUP(F15, Училища!A:F, 3, FALSE()), "")
A20: 2.6 | B20: Населено място: | F20: =IFERROR(VLOOKUP(F15, Училища!A:F, 4, FALSE()), "")
A21: 2.7 | B21: Вид училище: | F21: =IFERROR(VLOOKUP(F15, Училища!A:G, 7, FALSE()), "")
A22: 2.8 | B22: Детайлен вид на училище: | F22: =IFERROR(VLOOKUP(F15, Училища!A:V, 6, FALSE()), "")
A23: 2.9 | B23: Профил или професонално направление, ако има такива: | F23: Софтуерни и хардуерни науки, Чужди езици
A24: 2.1 | B24: Брой на учениците през учебната 2020-2021 г.: | F24: =IFERROR(VLOOKUP(F15, Училища!A:V, 8, FALSE()), "")
A25: 2.11 | B25: Брой на учениците през учебната 2021-2022 г.: | F25: =IFERROR(VLOOKUP(F15, Училища!A:V, 9, FALSE()), "")
A26: 2.12 | B26: Брой на учениците през учебната 2022-2023 г.: | F26: =IFERROR(VLOOKUP(F15, Училища!A:V, 10, FALSE()), "")
A27: 2.13 | B27: Средноаритметичен брой ученици за учебните 2020/2021, 2021/2022 и 2022/2023 учебна година | F27: =IFERROR(VLOOKUP(F15, Училища!A:V, 11, FALSE()), "")
A28: 2.14 | B28: Брой на педагогическия персонал за 2022-2023 г.: | F28: 85
A29: 2.15 | B29: Училището Ви има ли изграден STEM център към момента на кандидатстване? (Моля отбележете)
A31: 2.16 | B31: Вид на финансиране на училището: | F31: =IFERROR(VLOOKUP(F15, Училища!A:V, 7, FALSE()), "")
A32: 2.17 | B32: В кой/кои образователни етапи ще се използва центърът? (Можете да посочите повече от един)
A33: 2.18 | B33: Колко учители (и други специалисти) планирате да включите за работа в STEM среда в рамките на една учебна година? | F33: 6
A34: 2.19 | B34: Какъв е профилът на учителите, които планирате да бъдат включени в изграждането на STEM центъра? | F34: Учители по математика, информатика, информационни технологии, компютърно моделиране и информационни технологии
A35: 3 | B35: ВИДОВЕ РАЗХОДИ | I35: Максимален размер на средствата за изграждане на училищна STEM среда | J35: Искано финансиране за изграждане на училищна STEM среда
A36: 3.1 | B36: Средства STEM в лв. с ДДС | I36: =IFERROR(VLOOKUP(F15, Училища!A:V, 12, FALSE()), "") | J36: =J37+J38+J39+J40 -> 299575.46
A37: 3.2 | B37: в това число максимален размер на разходите за СМР и обзавеждане за STEM (до 45 % от средствата за STEM) в лв. с ДДС | I37: =IFERROR(VLOOKUP(F15, Училища!A:V, 13, FALSE()), "") | J37: =+'Направление 1'!H208+'Направление 1'!H211+'Направление 2'!H208+'Направление 2'!H211+'Направление 3'!H208+'Направление 3'!H211+'Направление 4'!H208+'Направление 4'!H211+'Направление 5'!H208+'Направление 5'!H211 -> 99126.528
A38: 3.3 | B38: в това число минимален размер на разходите за оборудване за STEM (минимум 45 % от средствата за STEM) в лв. с ДДС | I38: =IFERROR(VLOOKUP(F15, Училища!A:V, 14, FALSE()), "") | J38: =+'Направление 1'!H84++'Направление 2'!H84+'Направление 3'!H84+'Направление 4'!H84+'Направление 5'!H84 -> 170496.94
A39: 3.4 | B39: в това число максимален размер на разходите за допълнително специализирано оборудване за STEM (до 20 % от разходите за оборудване за STEM) в лв. с ДДС | I39: =IFERROR(VLOOKUP(F15, Училища!A:V, 15, FALSE()), "") | J39: =+'Специализирано оборудване'!H84 -> 0
A40: 3.5 | B40: в това число максимален размер на разходите за софтуер за STEM (до 10 % от средствата за STEM) в лв. с ДДС | I40: =IFERROR(VLOOKUP(F15, Училища!A:V, 16, FALSE()), "") | J40: =+'Направление 1'!H126+'Направление 2'!H126+'Направление 3'!H126+'Направление 4'!H126+'Направление 5'!H126+'Специализирано оборудване'!H126 -> 29952
A41: 3.6 | B41: Средства ВОСКС в лв. с ДДС | I41: =IFERROR(VLOOKUP(F15, Училища!A:V, 17, FALSE()), "") | J41: =+ВОСКС!H127 -> 59310
A42: 3.7 | B42: в това число максимален размер на разходите за софтуер за ВОСКС (до 10 % от средствата за ВОСКС) в лв. с ДДС | I42: =IFERROR(VLOOKUP(F15, Училища!A:V, 19, FALSE()), "") | J42: =+ВОСКС!H126 -> 5904
A43: 3.8 | B43: Общо средства (STEM и ВОСКС) в лв. с ДДС | I43: =IFERROR(VLOOKUP(F15, Училища!A:V, 20, FALSE()), "") | J43: =J36+J41 -> 358885.46
A44: 3.9 | B44: Средства за организация и управление (1%) от средствата за STEM и ВОСКС в лв. с ДДС | I44: =IFERROR(VLOOKUP(F15, Училища!A:V, 21, FALSE()), "") | J44: =+J43*0.01 -> 3588.8546
A45: 3.1 | B45: Общо средства за изграждане на училищна STEM среда в лв. с ДДС | I45: =IFERROR(VLOOKUP(F15, Училища!A:V, 22, FALSE()), "") | J45: =+J43+J44 -> 362474.32
A46: 4 | B46: Моля при подаване на попълнената Концепция за изграждане на училищна STEM среда да се приложат и следните задължителни документи:
...

Sheet Направление 1
A1: Остойностен списък с оборудване/обзавеждане/софтуер и СМР за направление „Роботика и кибер-физични системи“
A2: № по ред | B2: Наименование на оборудване/софтуер/обзавеждане/СМР | C2: Описание/Технически спецификации/характеристики | D2: Минимално ниво на оборудването по Направлението | E2: Количество | F2: Единична цена без ДДС (лева) | G2: Общо без ДДС (лева) | H2: Общо с ДДС (лева) | I2: Източник за формиране на единична цена на вид оборудване/софтуер/обзавеждане**
A3: Част I: Планирано за закупуване оборудване
A4: 1 | E4: 0 | F4: 0 | G4: =E4*F4 -> 0 | H4: =G4*1.2 -> 0
A5: 2 | E5: 0 | F5: 0 | G5: =E5*F5 -> 0 | H5: =G5*1.2 -> 0
A6: 3 | E6: 0 | F6: 0 | G6: =E6*F6 -> 0 | H6: =G6*1.2 -> 0
A7: 4 | E7: 0 | F7: 0 | G7: =E7*F7 -> 0 | H7: =G7*1.2 -> 0
A8: 5 | E8: 0 | F8: 0 | G8: =E8*F8 -> 0 | H8: =G8*1.2 -> 0
A9: 6 | E9: 0 | F9: 0 | G9: =E9*F9 -> 0 | H9: =G9*1.2 -> 0
A10: 7 | E10: 0 | F10: 0 | G10: =E10*F10 -> 0 | H10: =G10*1.2 -> 0
A11: 8 | E11: 0 | F11: 0 | G11: =E11*F11 -> 0 | H11: =G11*1.2 -> 0
A12: 9 | E12: 0 | F12: 0 | G12: =E12*F12 -> 0 | H12: =G12*1.2 -> 0
A13: 10 | E13: 0 | F13: 0 | G13: =E13*F13 -> 0 | H13: =G13*1.2 -> 0
A14: 11 | E14: 0 | F14: 0 | G14: =E14*F14 -> 0 | H14: =G14*1.2 -> 0
A15: 12 | E15: 0 | F15: 0 | G15: =E15*F15 -> 0 | H15: =G15*1.2 -> 0
... A83: 80 | E83: 0 | F83: 0 | G83: =E83*F83 -> 0 | H83: =G83*1.2 -> 0
A84: Общо разходи за оборудване | G84: =SUM(G4:G83) -> 0 | H84: =SUM(H4:H83) -> 0
B85: Част II: Планиран за закупуване софтуер
A86: 1 | D86: х | E86: 0 | F86: 0 | G86: =E86*F86 -> 0 | H86: =G86*1.2 -> 0
A87: 2 | D87: х | E87: 0 | F87: 0 | G87: =E87*F87 -> 0 | H87: =G87*1.2 -> 0
A88: 3 | D88: х | E88: 0 | F88: 0 | G88: =E88*F88 -> 0 | H88: =G88*1.2 -> 0
A89: 4 | D89: х | E89: 0 | F89: 0 | G89: =E89*F89 -> 0 | H89: =G89*1.2 -> 0
A90: 5 | D90: х | E90: 0 | F90: 0 | G90: =E90*F90 -> 0 | H90: =G90*1.2 -> 0
A91: 6 | D91: х | E91: 0 | F91: 0 | G91: =E91*F91 -> 0 | H91: =G91*1.2 -> 0
A92: 7 | D92: х | E92: 0 | F92: 0 | G92: =E92*F92 -> 0 | H92: =G92*1.2 -> 0
A93: 8 | D93: х | E93: 0 | F93: 0 | G93: =E93*F93 -> 0 | H93: =G93*1.2 -> 0
A94: 9 | D94: х | E94: 0 | F94: 0 | G94: =E94*F94 -> 0 | H94: =G94*1.2 -> 0
A95: 10 | D95: х | E95: 0 | F95: 0 | G95: =E95*F95 -> 0 | H95: =G95*1.2 -> 0
A96: 11 | D96: х | E96: 0 | F96: 0 | G96: =E96*F96 -> 0 | H96: =G96*1.2 -> 0
A97: 12 | D97: х | E97: 0 | F97: 0 | G97: =E97*F97 -> 0 | H97: =G97*1.2 -> 0
... A125: 40 | D125: х | E125: 0 | F125: 0 | G125: =E125*F125 -> 0 | H125: =G125*1.2 -> 0
A126: Общо разходи за софтуер | G126: =SUM(G86:G125) -> 0 | H126: =SUM(H86:H125) -> 0
B127: Част III: Планирано за закупуване обзавеждане
A128: 1 | D128: х | E128: 0 | F128: 0 | G128: =E128*F128 -> 0 | H128: =G128*1.2 -> 0
A129: 2 | D129: х | E129: 0 | F129: 0 | G129: =E129*F129 -> 0 | H129: =G129*1.2 -> 0
A130: 3 | D130: х | E130: 0 | F130: 0 | G130: =E130*F130 -> 0 | H130: =G130*1.2 -> 0
A131: 4 | D131: х | E131: 0 | F131: 0 | G131: =E131*F131 -> 0 | H131: =G131*1.2 -> 0
A132: 5 | D132: х | E132: 0 | F132: 0 | G132: =E132*F132 -> 0 | H132: =G132*1.2 -> 0
A133: 6 | D133: х | E133: 0 | F133: 0 | G133: =E133*F133 -> 0 | H133: =G133*1.2 -> 0
A134: 7 | D134: х | E134: 0 | F134: 0 | G134: =E134*F134 -> 0 | H134: =G134*1.2 -> 0
...

Sheet Направление 2
A1: Остойностен списък с оборудване/обзавеждане/софтуер и СМР за направление „Дизайн и 3D Прототипиране“
A2: № по ред | B2: Наименование на оборудване/софтуер/обзавеждане/СМР | C2: Описание/Технически спецификации/характеристики | D2: Минимално ниво на оборудването по Направлението | E2: Количество | F2: Единична цена без ДДС (лева) | G2: Общо без ДДС (лева) | H2: Общо с ДДС (лева) | I2: Източник за формиране на единична цена на вид оборудване/софтуер/обзавеждане**
A3: Част I: Планирано за закупуване оборудване
A4: 1 | E4: 0 | F4: 0 | G4: =E4*F4 -> 0 | H4: =G4*1.2 -> 0
A5: 2 | E5: 0 | F5: 0 | G5: =E5*F5 -> 0 | H5: =G5*1.2 -> 0
A6: 3 | E6: 0 | F6: 0 | G6: =E6*F6 -> 0 | H6: =G6*1.2 -> 0
A7: 4 | E7: 0 | F7: 0 | G7: =E7*F7 -> 0 | H7: =G7*1.2 -> 0
A8: 5 | E8: 0 | F8: 0 | G8: =E8*F8 -> 0 | H8: =G8*1.2 -> 0
A9: 6 | E9: 0 | F9: 0 | G9: =E9*F9 -> 0 | H9: =G9*1.2 -> 0
A10: 7 | E10: 0 | F10: 0 | G10: =E10*F10 -> 0 | H10: =G10*1.2 -> 0
A11: 8 | E11: 0 | F11: 0 | G11: =E11*F11 -> 0 | H11: =G11*1.2 -> 0
A12: 9 | E12: 0 | F12: 0 | G12: =E12*F12 -> 0 | H12: =G12*1.2 -> 0
A13: 10 | E13: 0 | F13: 0 | G13: =E13*F13 -> 0 | H13: =G13*1.2 -> 0
A14: 11 | E14: 0 | F14: 0 | G14: =E14*F14 -> 0 | H14: =G14*1.2 -> 0
A15: 12 | E15: 0 | F15: 0 | G15: =E15*F15 -> 0 | H15: =G15*1.2 -> 0
... A83: 80 | E83: 0 | F83: 0 | G83: =E83*F83 -> 0 | H83: =G83*1.2 -> 0
A84: Общо разходи за оборудване | G84: =SUM(G4:G83) -> 0 | H84: =SUM(H4:H83) -> 0
B85: Част II: Планиран за закупуване софтуер
A86: 1 | D86: х | E86: 0 | F86: 0 | G86: =E86*F86 -> 0 | H86: =G86*1.2 -> 0
A87: 2 | D87: х | E87: 0 | F87: 0 | G87: =E87*F87 -> 0 | H87: =G87*1.2 -> 0
A88: 3 | D88: х | E88: 0 | F88: 0 | G88: =E88*F88 -> 0 | H88: =G88*1.2 -> 0
A89: 4 | D89: х | E89: 0 | F89: 0 | G89: =E89*F89 -> 0 | H89: =G89*1.2 -> 0
A90: 5 | D90: х | E90: 0 | F90: 0 | G90: =E90*F90 -> 0 | H90: =G90*1.2 -> 0
A91: 6 | D91: х | E91: 0 | F91: 0 | G91: =E91*F91 -> 0 | H91: =G91*1.2 -> 0
A92: 7 | D92: х | E92: 0 | F92: 0 | G92: =E92*F92 -> 0 | H92: =G92*1.2 -> 0
A93: 8 | D93: х | E93: 0 | F93: 0 | G93: =E93*F93 -> 0 | H93: =G93*1.2 -> 0
A94: 9 | D94: х | E94: 0 | F94: 0 | G94: =E94*F94 -> 0 | H94: =G94*1.2 -> 0
A95: 10 | D95: х | E95: 0 | F95: 0 | G95: =E95*F95 -> 0 | H95: =G95*1.2 -> 0
A96: 11 | D96: х | E96: 0 | F96: 0 | G96: =E96*F96 -> 0 | H96: =G96*1.2 -> 0
A97: 12 | D97: х | E97: 0 | F97: 0 | G97: =E97*F97 -> 0 | H97: =G97*1.2 -> 0
... A125: 40 | D125: х | E125: 0 | F125: 0 | G125: =E125*F125 -> 0 | H125: =G125*1.2 -> 0
A126: Общо разходи за софтуер | G126: =SUM(G86:G125) -> 0 | H126: =SUM(H86:H125) -> 0
B127: Част III: Планирано за закупуване обзавеждане
A128: 1 | D128: х | E128: 0 | F128: 0 | G128: =E128*F128 -> 0 | H128: =G128*1.2 -> 0
A129: 2 | D129: х | E129: 0 | F129: 0 | G129: =E129*F129 -> 0 | H129: =G129*1.2 -> 0
A130: 3 | D130: х | E130: 0 | F130: 0 | G130: =E130*F130 -> 0 | H130: =G130*1.2 -> 0
A131: 4 | D131: х | E131: 0 | F131: 0 | G131: =E131*F131 -> 0 | H131: =G131*1.2 -> 0
A132: 5 | D132: х | E132: 0 | F132: 0 | G132: =E132*F132 -> 0 | H132: =G132*1.2 -> 0
A133: 6 | D133: х | E133: 0 | F133: 0 | G133: =E133*F133 -> 0 | H133: =G133*1.2 -> 0
A134: 7 | D134: х | E134: 0 | F134: 0 | G134: =E134*F134 -> 0 | H134: =G134*1.2 -> 0
...

Sheet Направление 3
A1: Остойностен списък с оборудване/обзавеждане/софтуер и СМР за направление „Природни науки“
A2: № по ред | B2: Наименование на оборудване/софтуер/обзавеждане/СМР | C2: Описание/Технически спецификации/характеристики | D2: Минимално ниво на оборудването по Направлението | E2: Количество | F2: Единична цена без ДДС (лева) | G2: Общо без ДДС (лева) | H2: Общо с ДДС (лева) | I2: Източник за формиране на единична цена на вид оборудване/софтуер/обзавеждане**
A3: Част I: Планирано за закупуване оборудване
A4: 1 | E4: 0 | F4: 0 | G4: =E4*F4 -> 0 | H4: =G4*1.2 -> 0
A5: 2 | E5: 0 | F5: 0 | G5: =E5*F5 -> 0 | H5: =G5*1.2 -> 0
A6: 3 | E6: 0 | F6: 0 | G6: =E6*F6 -> 0 | H6: =G6*1.2 -> 0
A7: 4 | E7: 0 | F7: 0 | G7: =E7*F7 -> 0 | H7: =G7*1.2 -> 0
A8: 5 | E8: 0 | F8: 0 | G8: =E8*F8 -> 0 | H8: =G8*1.2 -> 0
A9: 6 | E9: 0 | F9: 0 | G9: =E9*F9 -> 0 | H9: =G9*1.2 -> 0
A10: 7 | E10: 0 | F10: 0 | G10: =E10*F10 -> 0 | H10: =G10*1.2 -> 0
A11: 8 | E11: 0 | F11: 0 | G11: =E11*F11 -> 0 | H11: =G11*1.2 -> 0
A12: 9 | E12: 0 | F12: 0 | G12: =E12*F12 -> 0 | H12: =G12*1.2 -> 0
A13: 10 | E13: 0 | F13: 0 | G13: =E13*F13 -> 0 | H13: =G13*1.2 -> 0
A14: 11 | E14: 0 | F14: 0 | G14: =E14*F14 -> 0 | H14: =G14*1.2 -> 0
A15: 12 | E15: 0 | F15: 0 | G15: =E15*F15 -> 0 | H15: =G15*1.2 -> 0
... A83: 80 | E83: 0 | F83: 0 | G83: =E83*F83 -> 0 | H83: =G83*1.2 -> 0
A84: Общо разходи за оборудване | G84: =SUM(G4:G83) -> 0 | H84: =SUM(H4:H83) -> 0
B85: Част II: Планиран за закупуване софтуер
A86: 1 | D86: х | E86: 0 | F86: 0 | G86: =E86*F86 -> 0 | H86: =G86*1.2 -> 0
A87: 2 | D87: х | E87: 0 | F87: 0 | G87: =E87*F87 -> 0 | H87: =G87*1.2 -> 0
A88: 3 | D88: х | E88: 0 | F88: 0 | G88: =E88*F88 -> 0 | H88: =G88*1.2 -> 0
A89: 4 | D89: х | E89: 0 | F89: 0 | G89: =E89*F89 -> 0 | H89: =G89*1.2 -> 0
A90: 5 | D90: х | E90: 0 | F90: 0 | G90: =E90*F90 -> 0 | H90: =G90*1.2 -> 0
A91: 6 | D91: х | E91: 0 | F91: 0 | G91: =E91*F91 -> 0 | H91: =G91*1.2 -> 0
A92: 7 | D92: х | E92: 0 | F92: 0 | G92: =E92*F92 -> 0 | H92: =G92*1.2 -> 0
A93: 8 | D93: х | E93: 0 | F93: 0 | G93: =E93*F93 -> 0 | H93: =G93*1.2 -> 0
A94: 9 | D94: х | E94: 0 | F94: 0 | G94: =E94*F94 -> 0 | H94: =G94*1.2 -> 0
A95: 10 | D95: х | E95: 0 | F95: 0 | G95: =E95*F95 -> 0 | H95: =G95*1.2 -> 0
A96: 11 | D96: х | E96: 0 | F96: 0 | G96: =E96*F96 -> 0 | H96: =G96*1.2 -> 0
A97: 12 | D97: х | E97: 0 | F97: 0 | G97: =E97*F97 -> 0 | H97: =G97*1.2 -> 0
... A125: 40 | D125: х | E125: 0 | F125: 0 | G125: =E125*F125 -> 0 | H125: =G125*1.2 -> 0
A126: Общо разходи за софтуер | G126: =SUM(G86:G125) -> 0 | H126: =SUM(H86:H125) -> 0
B127: Част III: Планирано за закупуване обзавеждане
A128: 1 | D128: х | E128: 0 | F128: 0 | G128: =E128*F128 -> 0 | H128: =G128*1.2 -> 0
A129: 2 | D129: х | E129: 0 | F129: 0 | G129: =E129*F129 -> 0 | H129: =G129*1.2 -> 0
A130: 3 | D130: х | E130: 0 | F130: 0 | G130: =E130*F130 -> 0 | H130: =G130*1.2 -> 0
A131: 4 | D131: х | E131: 0 | F131: 0 | G131: =E131*F131 -> 0 | H131: =G131*1.2 -> 0
A132: 5 | D132: х | E132: 0 | F132: 0 | G132: =E132*F132 -> 0 | H132: =G132*1.2 -> 0
A133: 6 | D133: х | E133: 0 | F133: 0 | G133: =E133*F133 -> 0 | H133: =G133*1.2 -> 0
A134: 7 | D134: х | E134: 0 | F134: 0 | G134: =E134*F134 -> 0 | H134: =G134*1.2 -> 0
...

Sheet Направление 4
A1: Остойностен списък с оборудване/обзавеждане/софтуер и СМР за направление „Зелени технологии и устойчиво развитие“
A2: № по ред | B2: Наименование на оборудване/софтуер/обзавеждане/СМР | C2: Описание/Технически спецификации/характеристики | D2: Минимално ниво на оборудването по Направлението | E2: Количество | F2: Единична цена без ДДС (лева) | G2: Общо без ДДС (лева) | H2: Общо с ДДС (лева) | I2: Източник за формиране на единична цена на вид оборудване/софтуер/обзавеждане**
A3: Част I: Планирано за закупуване оборудване
A4: 1 | E4: 0 | F4: 0 | G4: =E4*F4 -> 0 | H4: =G4*1.2 -> 0
A5: 2 | E5: 0 | F5: 0 | G5: =E5*F5 -> 0 | H5: =G5*1.2 -> 0
A6: 3 | E6: 0 | F6: 0 | G6: =E6*F6 -> 0 | H6: =G6*1.2 -> 0
A7: 4 | E7: 0 | F7: 0 | G7: =E7*F7 -> 0 | H7: =G7*1.2 -> 0
A8: 5 | E8: 0 | F8: 0 | G8: =E8*F8 -> 0 | H8: =G8*1.2 -> 0
A9: 6 | E9: 0 | F9: 0 | G9: =E9*F9 -> 0 | H9: =G9*1.2 -> 0
A10: 7 | E10: 0 | F10: 0 | G10: =E10*F10 -> 0 | H10: =G10*1.2 -> 0
A11: 8 | E11: 0 | F11: 0 | G11: =E11*F11 -> 0 | H11: =G11*1.2 -> 0
A12: 9 | E12: 0 | F12: 0 | G12: =E12*F12 -> 0 | H12: =G12*1.2 -> 0
A13: 10 | E13: 0 | F13: 0 | G13: =E13*F13 -> 0 | H13: =G13*1.2 -> 0
A14: 11 | E14: 0 | F14: 0 | G14: =E14*F14 -> 0 | H14: =G14*1.2 -> 0
A15: 12 | E15: 0 | F15: 0 | G15: =E15*F15 -> 0 | H15: =G15*1.2 -> 0
... A83: 80 | E83: 0 | F83: 0 | G83: =E83*F83 -> 0 | H83: =G83*1.2 -> 0
A84: Общо разходи за оборудване | G84: =SUM(G4:G83) -> 0 | H84: =SUM(H4:H83) -> 0
B85: Част II: Планиран за закупуване софтуер
A86: 1 | D86: х | E86: 0 | F86: 0 | G86: =E86*F86 -> 0 | H86: =G86*1.2 -> 0
A87: 2 | D87: х | E87: 0 | F87: 0 | G87: =E87*F87 -> 0 | H87: =G87*1.2 -> 0
A88: 3 | D88: х | E88: 0 | F88: 0 | G88: =E88*F88 -> 0 | H88: =G88*1.2 -> 0
A89: 4 | D89: х | E89: 0 | F89: 0 | G89: =E89*F89 -> 0 | H89: =G89*1.2 -> 0
A90: 5 | D90: х | E90: 0 | F90: 0 | G90: =E90*F90 -> 0 | H90: =G90*1.2 -> 0
A91: 6 | D91: х | E91: 0 | F91: 0 | G91: =E91*F91 -> 0 | H91: =G91*1.2 -> 0
A92: 7 | D92: х | E92: 0 | F92: 0 | G92: =E92*F92 -> 0 | H92: =G92*1.2 -> 0
A93: 8 | D93: х | E93: 0 | F93: 0 | G93: =E93*F93 -> 0 | H93: =G93*1.2 -> 0
A94: 9 | D94: х | E94: 0 | F94: 0 | G94: =E94*F94 -> 0 | H94: =G94*1.2 -> 0
A95: 10 | D95: х | E95: 0 | F95: 0 | G95: =E95*F95 -> 0 | H95: =G95*1.2 -> 0
A96: 11 | D96: х | E96: 0 | F96: 0 | G96: =E96*F96 -> 0 | H96: =G96*1.2 -> 0
A97: 12 | D97: х | E97: 0 | F97: 0 | G97: =E97*F97 -> 0 | H97: =G97*1.2 -> 0
... A125: 40 | D125: х | E125: 0 | F125: 0 | G125: =E125*F125 -> 0 | H125: =G125*1.2 -> 0
A126: Общо разходи за софтуер | G126: =SUM(G86:G125) -> 0 | H126: =SUM(H86:H125) -> 0
B127: Част III: Планирано за закупуване обзавеждане
A128: 1 | D128: х | E128: 0 | F128: 0 | G128: =E128*F128 -> 0 | H128: =G128*1.2 -> 0
A129: 2 | D129: х | E129: 0 | F129: 0 | G129: =E129*F129 -> 0 | H129: =G129*1.2 -> 0
A130: 3 | D130: х | E130: 0 | F130: 0 | G130: =E130*F130 -> 0 | H130: =G130*1.2 -> 0
A131: 4 | D131: х | E131: 0 | F131: 0 | G131: =E131*F131 -> 0 | H131: =G131*1.2 -> 0
A132: 5 | D132: х | E132: 0 | F132: 0 | G132: =E132*F132 -> 0 | H132: =G132*1.2 -> 0
A133: 6 | D133: х | E133: 0 | F133: 0 | G133: =E133*F133 -> 0 | H133: =G133*1.2 -> 0
A134: 7 | D134: х | E134: 0 | F134: 0 | G134: =E134*F134 -> 0 | H134: =G134*1.2 -> 0
...

Sheet Направление 5
A1: Остойностен списък с оборудване/обзавеждане/софтуер и СМР за направление „Математика и Информатика“
A2: № по ред | B2: Наименование на оборудване/софтуер/обзавеждане/СМР | C2: Описание/Технически спецификации/характеристики | D2: Минимално ниво на оборудването по Направлението | E2: Количество | F2: Единична цена без ДДС (лева) | G2: Общо без ДДС (лева) | H2: Общо с ДДС (лева) | I2: Източник за формиране на единична цена на вид оборудване/софтуер/обзавеждане**
A3: Част I: Планирано за закупуване оборудване
A4: 1 | B4: преносим компютър | C4: Процесор: 3.30 GHz, 10 MB cache Памет: 8GB 3200GHz DDR4 Диск: SSD 512GB Дисплей: 15.6'' , 1920x1080 dpi Мрежа: 10/100/1000 Mbps Безжична мрежа: 802.11ac 1x1 WiFi, Bluetooth Портове, 1 х USB 3.2 Gen 1, 1 х USB 2.0, 1 х HDMI Web камера: HD cam Кирилизация БДС кирилизация на клавиатурата Инсталирана операционна система | D4: преносим компютър | E4: 45 | F4: 1232.5 | G4: =E4*F4 -> 55462.5 | H4: =G4*1.2 -> 66555 | I4: https://www.ozone.bg/product/laptop-dell-vostro-3530-intel-core-5-1335u-12-mb-cache-up-to-4-60-ghz-15-6-fhd-1920x1080-ag-120hz-wva-250nits-8gb-1x8gb-ddr4-512gb-pcie-m-2-uhd-graphics-hd-cam-and-mic-802-11ac-bg-kb-win-11-pro-3y-bos/ - 1699 лв с ДДС https://ardes.bg/product/dell-vostro-3520-n1614pvnb3520emea01-ubu-16gb-w11h-317367 - 1178 лв с ддс
A5: 2 | B5: Интерактивен дисплей с широкоъгълна камера и микрофон | C5: 65-инчов 4K интерактивен плосък панел с камера и микрофон, с OPS/OPS-C устройства, реализирайки плавно превключване между вградените системи. | D5: интерактивен дисплей | E5: 3 | F5: 6185 | G5: =E5*F5 -> 18555 | H5: =G5*1.2 -> 22266 | I5: https://ont.bg/bg-product-details-158.html - 6048 лв с ддс https://www.jmt.bg/newline-tt-6522z-pid78504 - 8897 лв с ддс
A6: 3 | B6: Рутер, 5.4Gbps, черен | C6: Брой антени 6 Тип охлаждане Пасивно Wi-Fi скорост (Mbps) до 5400 Сигурност WPA/WPA2-Enterprise, WPA2, WPA3 Портове USB 3, RJ45 Цвят Черен Тегло 1.554 kg Подходящ за За дома, Офиса, Работа Интерес Технологии Размер на опаковката 33 x 12.3 x 26.7 cm Гаранция 36 месеца | D6: мрежово оборудване | E6: 3 | F6: 358.89 | G6: =E6*F6 -> 1076.67 | H6: =G6*1.2 -> 1292.004 | I6: https://www.ozone.bg/product/ruter-ubiquiti-edgerouter-4-er-4/ - 424.15 лв с ддс https://www.senetic.bg/product/Archer_AXE75?gclid=CjwKCAjwhJukBhBPEiwAniIcNbRIJRtkjYYCUmD0ZTKvhfRwv3d1ujC9Ky3D1i7maGRIk-r1MpMNKxoC7zwQAvD_BwE - 424.52 лв с ддс
A7: 4 | B7: Очила за виртуална реалност | C7: Дисплей: LCD (1832x1920) двоен дисплей Вградена памет: 128 GB Интерфейс: USB Type C Аудио: Вградени говорители Сензори: Акселерометър Жироскоп Сензор за близост Лазерни сензори за позициониране Размер: 260 x 180.7 x 126 мм Тегло: 830 г Съвместимост: със смартфони с инсталирано приложение Аксесоари: контролери за допир в комплекта Гаранционен срок: 24 месеца гаранция | D7: 3D очила | E7: 28 | F7: 857.5 | G7: =E7*F7 -> 24010 | H7: =G7*1.2 -> 28812 | I7: https://ardes.bg/product/oculus-quest-2-128gb-all-in-one-byal-301-00355-01-276169?utm_source=pazaruvaj.com&utm_medium=VR+%D0%BE%D1%87%D0%B8%D0%BB%D0%B0 949 лв с ддс https://bestpc.bg/bg/aksesoari-drugi/facebook/komplekt-za-virtualna-realnost-oculus-quest-2-256gb-295270 1109 лв с ддс
A8: 5 | B8: Платки | C8: Комплект за програмиране с многобройни компоненти | D8: контролерни платки с микроконтролери или микропроцесори | E8: 3 | F8: 56.3 | G8: =E8*F8 -> 168.9 | H8: =G8*1.2 -> 202.68 | I8: https://vikiwat.com/prototipna-platka-razvoen-komplekt-arduino-uno-rev3-bg.html 75.11лв с ддс https://erelement.com/arduino-ethernet-shield-2 60лв с ддс
A9: 6 | B9: Режещ плотер | C9: Максимална ширина на медията 719 мм Максимална ширина на рязане 600 мм Тип на моторите Стъпков Максимална скорост на рязане 705 мм/сек Максимална дебелина на медията 0.8 мм Натиск на ножа до 350 гр Система за засичане на пасери и рязане на отпечатани изображения по контур не Механична резолюция 0.006 мм Софтуерна резолюция 0.025 мм Повторяемост ± 0.1 мм Начална точка на рязане Да Перфорация Да Размножаване Да Повторение Да Памет/буфер 512 КB Софтуер Дисплей за управление 6 LED, 10 бутона Диаметър на ножчетата 2.5 мм Размери 233 х 255 х 880 мм. Захранване 100 to 240 V AC, 50/60 Hz Работна среда 15'C to 30'C, 25% to 75% RH | D9: плотер | E9: 2 | F9: 1007.9 | G9: =E9*F9 -> 2015.8 | H9: =G9*1.2 -> 2418.96 | I9: https://www.adcom.bg/produkti/rejeshti-ploteri/rolni/expert-ii-24-detail 1432.8 с ддс https://hansbg.com/product/7781/rezhesht-ploter-expert-ii-24-lx.html 986.15лв
A10: 7 | B10: 3D Принтер | C10: Технология на 3D печат: FDM или еквивалент; Тип на използваните материали: минимум PLA или еквивалент; Размери на работната област за изграждане на модели минимум: 280х190х160mm; Скорост на изграждане: до 100 mm/s; Точност на изграждане: 0.2 mm; Височина на слоя при изграждане: 0.1 до 0.3 mm; Диаметър на филамент: минимум 1.75mm. Дюза: минимум 1 брой, диаметър: 0.4 mm, температура на нагряване на дюзата: минимум до 190° C; Температура на работна област за изграждане: минимум до 60° C; Екран; Софтуер за управление и подготовка на детайли за печат. | D10: 3D Принтер | E10: 2 | F10: 990.89 | G10: =E10*F10 -> 1981.78 | H10: =G10*1.2 -> 2378.136 | I10: https://www.emag.bg/3d-printer-wanhao-duplicator-7-plus-dlp-12x6-8x18-cm-cveten-tychskrijn-d7plus/pd/DXRWR5BBM/?_gl=1*6kclas*_up*MQ..&gclid=CjwKCAjwyqWkBhBMEiwAp2yUFkYUEmmdIPZQRpb7r8RhSc5fuPE-usVOuKwoUd5gWSWfMMAcqEOQlxoC5hwQAvD_BwE - 1213,20 лв с ддс https://3dprintx.bg/magazin/k1c-creality/ - 1228 лв.с ддс
A11: 8 | B11: HDMI кабел | C11: HDMI кабел 15м | D11: мрежово оборудване | E11: 10 | F11: 82.5 | G11: =E11*F11 -> 825 | H11: =G11*1.2 -> 990 | I11: https://dice.bg/belkin-8k-ultra-high-speed-hdmi-cable-with-dolby-vision-hdmi-kabel-s-poddrazhka-na-dolby-vision-200-sm-cheren-item36117/ - 99 лв с ддс https://www.jarcomputers.com/belkin-8k-ultra-high-speed-hdmi-cable-with-dolby-vision-hdmi-kabel-s-poddryjka-na-dolby-vi_sprod_413629.html - 99 лв с ддс
A12: 9 | B12: суич-комутатор | C12: Вид продукт Суич Напрежение 100 - 240 V Честота 50/60 Hz Температура -5°C - 40°C Портове LAN 10/100 Mbps, 16 x 10/100/1000Mbps Wifi Стандарт IEEE 802.3 at, IEEE 802.3ad, IEEE 802.3af Ethernet скорост 10/100/1000 Mbps Тип охлаждане Активно Сигурност ESD/EMP Портове 2x SFP Цвят Бял Подходящ за Бизнес, За дома, Офиса, Работа Размер на продукта 44.3 x 4.37 x 20 cm Гаранция 24 месеца Тегло на продукта 2.8 kg | D12: мрежово оборудване | E12: 2 | F12: 662.68 | G12: =E12*F12 -> 1325.36 | H12: =G12*1.2 -> 1590.432 | I12: https://www.ozone.bg/product/16-portov-gigabiten-komutator-ubiquiti-usw-16-poe-gen2/ 999 лв с ддс https://www.senetic.bg/product/USW-16-POE?gclid=CjwKCAjwhJukBhBPEiwAniIcNfnBbHTFT4xonsu4nT9CzpPaEG_NgTyeqUMPj0BDPhBoANkb_5y2ahoC0RwQAvD_BwE 591,43 лв с ДДС
A13: 10 | B13: видеорегистратор | C13: Видео компресия H.265/H.264 Резолюция на кодиране Поток с висока разделителна способност: 1080p/720p/WD1/4CIF/VGA/CIF Поток със стандартна разделителна способност: WD1/4CIF/CIF Плавен поток: CIF/QVGA Честота на кадрите 1 до 25 fps (P)/30 fps (N) Видео битрейт 32 Kbps до 16 Mbps Тип поток Видео и аудио, видео Аудио компресия AAC Аудио битрейт 128 Kbps Видео и аудио IP видео вход 5-канал; До 2 MP резолюция; Поддържа H.265/H.264 IP камери Аналогов видео вход 8-кан; наличие на интерфейс ; 1080p/25 fps, 1080p/30 fps, 720p/25 fps, 720p/30 fps, 720p/50 fps, 720p/60 fps; Възможност за свързване към CVBS сигнал HDMI изход 1-канал; 1024 × 768/60 Hz, 1280 × 720/60 Hz, 1280 × 1024/60 Hz, 1920 × 1080/60 Hz VGA изход 1-канал; 1024 × 768/60 Hz, 1280 × 720/60 Hz, 1280 × 1024/60 Hz, 1920 × 1080/60 Hz HDMI вход 2-канал; 1024 × 768, 1280 × 720, 1366 × 768, 1680 × 1050, 1920 × 1080; HDMI и VGA не могат да бъдат разпознати синхронно в една и съща група VGA вход 2 канала; 1024 × 768, 1280 × 720, 1366 × 768, 1680 × 1050, 1920 × 1080; HDMI и VGA не могат да бъдат разпознати синхронно в една и съща група HDMI Loopback 1 канал (съвпадение на HDMI видео в 1) VGA Loopback 1 канал (съвпадение на VGA видео в 1) Аудио изход 1-канален двоен канал на 3,5 мм конектор 1-канален двоен канал на RCA конектор 2-канален единичен канал на зелен конектор. Линеен Нивел; Импеданс: 1 KΩ Аудио вход 1-канален двоен канал на 3,5 мм конектор 1-канален двоен канал на RCA конектор. Честота на дискретизация: 48 KHz 6-канален единичен канал на зелен конектор. Честота на дискретизация: 48 KHz Честота на аудио дискретизация 48 KHz Декодиране Синхронно възпроизвеждане 1-гл Двоен поток поддържа | D13: друго | E13: 2 | F13: 4100 | G13: =E13*F13 -> 8200 | H13: =G13*1.2 -> 9840 | I13: оферта №1 Тех Смарт ЕООД 18.08.2023 и №4 от 13.08.23г.
A14: 11 | B14: камери | C14: 3840 x 2160 Резолюция при 30 кадъра в секунда IR осветление до 98' 2.8-12mm варифокален обектив 112,3 до 41,2° хоризонтално зрително поле Двупосочно аудио microSD слот поддържа до 256GB Ethernet порт с технология IK10-номинална вандалска устойчивост | D14: друго | E14: 2 | F14: 1171.58 | G14: =E14*F14 -> 2343.16 | H14: =G14*1.2 -> 2811.792 | I14: https://www.bhphotovideo.com/c/product/1702838-REG/hikvision_ids_2cd7186g0_izs_2_812_mm_deepinview_ids_2cd7186g0_izs_8mp_network.html 1049.39 лв https://www.networkcamerastore.com/hikvision-ids-2cd7186g0-izs-8-32mm-8mp-deepinview-m-vf-in-o-dome/ 1762.4 лв
A15: 12 | B15: камери | C15: Висококачествени изображения с 8 МР резолюция Отлична производителност при слаба светлина Ефективна технология за компресиране +, за да спести честотна лента и съхранение Ясни изображения срещу силна задна светлина благодарение на 120 dB истинска WDR технология 5 потока, за да отговарят на голямо разнообразие от приложения Вандал доказателство (IK10) | D15: друго | E15: 2 | F15: 1171.58 | G15: =E15*F15 -> 2343.16 | H15: =G15*1.2 -> 2811.792 | I15: https://www.networkcamerastore.com/hikvision-ids-2cd7186g0-izs-8-32mm-8mp-deepinview-m-vf-in-o-dome/ 1762.40 лв https://www.bhphotovideo.com/c/product/1702838-REG/hikvision_ids_2cd7186g0_izs_2_812_mm_deepinview_ids_2cd7186g0_izs_8mp_network.html 1049.39лв
... A20: 17 | B20: мултифункционално устройство | C20: Поддържан формат на хартията до SRA3 Стандартна памет от 8 GB RAM 25 ppm, за да бъдете в крак с нарастващото натоварване Капацитет на зареждане с хартията до 6 650 листа Скорост при цветно сканиране до 200 ipmПълна интеграция със система за управление на печата | D20: принтер | E20: 1 | F20: 5417.5 | G20: =E20*F20 -> 5417.5 | H20: =G20*1.2 -> 6501 | I20: https://mpsbulgaria.com/produkti/harduer/multifunkcionalni-ustroystva/konica-minolta-bizhub-c250i-multifunkcionalno-ustroystvo.html https://dilex.bg/pechat/kopirni-mashini/cveten-pechat/konica-minolta-bizhub-c250i-nov-model-sra3-cvetna-kopirna-mashina.osnovno-tyalo-cveten-kopir-cveten-skener-i-dvustranen-cveten-printer.300gr.hartiya.html
A21: 18 | E21: 0 | F21: 0 | G21: =E21*F21 -> 0 | H21: =G21*1.2 -> 0
A22: 19 | E22: 0 | F22: 0 | G22: =E22*F22 -> 0 | H22: =G22*1.2 -> 0
A23: 20 | E23: 0 | F23: 0 | G23: =E23*F23 -> 0 | H23: =G23*1.2 -> 0
A24: 21 | E24: 0 | F24: 0 | G24: =E24*F24 -> 0 | H24: =G24*1.2 -> 0
A25: 22 | E25: 0 | F25: 0 | G25: =E25*F25 -> 0 | H25: =G25*1.2 -> 0
A26: 23 | E26: 0 | F26: 0 | G26: =E26*F26 -> 0 | H26: =G26*1.2 -> 0
A27: 24 | E27: 0 | F27: 0 | G27: =E27*F27 -> 0 | H27: =G27*1.2 -> 0
A28: 25 | E28: 0 | F28: 0 | G28: =E28*F28 -> 0 | H28: =G28*1.2 -> 0
A29: 26 | E29: 0 | F29: 0 | G29: =E29*F29 -> 0 | H29: =G29*1.2 -> 0
A30: 27 | E30: 0 | F30: 0 | G30: =E30*F30 -> 0 | H30: =G30*1.2 -> 0
A31: 28 | E31: 0 | F31: 0 | G31: =E31*F31 -> 0 | H31: =G31*1.2 -> 0
A32: 29 | E32: 0 | F32: 0 | G32: =E32*F32 -> 0 | H32: =G32*1.2 -> 0
... A83: 80 | E83: 0 | F83: 0 | G83: =E83*F83 -> 0 | H83: =G83*1.2 -> 0
A84: Общо разходи за оборудване | G84: =SUM(G4:G83) -> 142080.78 | H84: =SUM(H4:H83) -> 170496.94
B85: Част II: Планиран за закупуване софтуер
A86: 1 | B86: Софтуер за редакция на изображения и графики | C86: професионален графичен софтуер, предназначен за обработка на изображения.Предлага богат набор от инструменти и функции, включително редактор за корекции на цветове, създаване на слоеве, ретуш и множество филтри, които подпомагат при създаването, редактирането и подобряването на графични проекти. | D86: х | E86: 27 | F86: 540 | G86: =E86*F86 -> 14580 | H86: =G86*1.2 -> 17496 | I86: https://www.adobe.com/bg/creativecloud/plans.html https://pixlr.com/pricing/
A87: 2 | B87: Софтуер за дигитализация на учебния процес | C87: Софтуер в подкрепа на дигиталната трансформация в образованието | D87: х | E87: 1 | F87: 5200 | G87: =E87*F87 -> 5200 | H87: =G87*1.2 -> 6240 | I87: Оферта 1 от 18.08.2023 и №6 31.07.23г.
A88: 3 | B88: софтуер за централизирано управление на интерактивни дисплеи | C88: софтуер за централизирано управление на дисплеи -Поддържани медийни формати: DAT, MPG, VOB, TS, AVI, MKV, MPS, MOV, 3GP, TS, FLV, WEBM, ASF, MP1, MP2, MP3, WMA, WAV, OGG, OGA, FLAC, ACC, M4A, XMF, MXMF, RTTTL, RTX, OTA, IMY, JPG, JPEG, BMP, GIF, PNG | D88: х | E88: 1 | F88: 5180 | G88: =E88*F88 -> 5180 | H88: =G88*1.2 -> 6216 | I88: Оферта 1 от 18.08.2023 и №6 31.07.23г.
A89: 4 | D89: х | E89: 0 | F89: 0 | G89: =E89*F89 -> 0 | H89: =G89*1.2 -> 0
A90: 5 | D90: х | E90: 0 | F90: 0 | G90: =E90*F90 -> 0 | H90: =G90*1.2 -> 0
A91: 6 | D91: х | E91: 0 | F91: 0 | G91: =E91*F91 -> 0 | H91: =G91*1.2 -> 0
A92: 7 | D92: х | E92: 0 | F92: 0 | G92: =E92*F92 -> 0 | H92: =G92*1.2 -> 0
A93: 8 | D93: х | E93: 0 | F93: 0 | G93: =E93*F93 -> 0 | H93: =G93*1.2 -> 0
A94: 9 | D94: х | E94: 0 | F94: 0 | G94: =E94*F94 -> 0 | H94: =G94*1.2 -> 0
...

Sheet ВОСКС
A1: Остойностен списък с оборудване/софтуер за високотехнологични оборудвани и свързани класни стаи
A2: № по ред | B2: Наименование на оборудване/софтуер/СМР | C2: Описание/Технически спецификации/характеристики | D2: Минимално ниво на оборудването по Направлението | E2: Количество | F2: Единична цена без ДДС (лева) | G2: Общо без ДДС (лева) | H2: Общо с ДДС (лева) | I2: Източник за формиране на единична цена на вид оборудване/софтуер/обзавеждане**
A3: Част I: Планирано за закупуване оборудване
A4: 1 | B4: Интерактивен дисплей с широкоъгълна камера и микрофон | C4: 65-инчов 4K интерактивен плосък панел с камера и микрофон, с OPS/OPS-C устройства, реализирайки плавно превключване между вградените системи. | D4: интерактивен дисплей с вграден компютърен OPS модул и вградена точка за достъп с интегрирана широкоъгълна камера и микрофон | E4: 6 | F4: 6185 | G4: =E4*F4 -> 37110 | H4: =G4*1.2 -> 44532 | I4: https://ont.bg/bg-product-details-158.html - 6048 лв с ддс https://www.jmt.bg/newline-tt-6522z-pid78504 - 8897 лв с ддс
A5: 2 | B5: преносим компютър | C5: Процесор: 3.30 GHz, 10 MB cache Памет: 8GB 3200GHz DDR4 Диск: SSD 512GB Дисплей: 15.6'' , 1920x1080 dpi Мрежа: 10/100/1000 Mbps Безжична мрежа: 802.11ac 1x1 WiFi, Bluetooth Портове, 1 х USB 3.2 Gen 1, 1 х USB 2.0, 1 х HDMI Web камера: HD cam Кирилизация БДС кирилизация на клавиатурата Инсталирана операционна система | D5: преносим компютър | E5: 6 | F5: 1232.5 | G5: =E5*F5 -> 7395 | H5: =G5*1.2 -> 8874 | I5: https://www.ozone.bg/product/laptop-dell-vostro-3530-intel-core-5-1335u-12-mb-cache-up-to-4-60-ghz-15-6-fhd-1920x1080-ag-120hz-wva-250nits-8gb-1x8gb-ddr4-512gb-pcie-m-2-uhd-graphics-hd-cam-and-mic-802-11ac-bg-kb-win-11-pro-3y-bos/ - 1699 лв с ДДС https://ardes.bg/product/dell-vostro-3520-n1614pvnb3520emea01-ubu-16gb-w11h-317367 - 1178 лв с ддс
A6: 3 | E6: 0 | F6: 0 | G6: =E6*F6 -> 0 | H6: =G6*1.2 -> 0
A7: 4 | E7: 0 | F7: 0 | G7: =E7*F7 -> 0 | H7: =G7*1.2 -> 0
A8: 5 | E8: 0 | F8: 0 | G8: =E8*F8 -> 0 | H8: =G8*1.2 -> 0
A9: 6 | E9: 0 | F9: 0 | G9: =E9*F9 -> 0 | H9: =G9*1.2 -> 0
A10: 7 | E10: 0 | F10: 0 | G10: =E10*F10 -> 0 | H10: =G10*1.2 -> 0
A11: 8 | E11: 0 | F11: 0 | G11: =E11*F11 -> 0 | H11: =G11*1.2 -> 0
A12: 9 | E12: 0 | F12: 0 | G12: =E12*F12 -> 0 | H12: =G12*1.2 -> 0
A13: 10 | E13: 0 | F13: 0 | G13: =E13*F13 -> 0 | H13: =G13*1.2 -> 0
A14: 11 | E14: 0 | F14: 0 | G14: =E14*F14 -> 0 | H14: =G14*1.2 -> 0
A15: 12 | E15: 0 | F15: 0 | G15: =E15*F15 -> 0 | H15: =G15*1.2 -> 0
A16: 13 | E16: 0 | F16: 0 | G16: =E16*F16 -> 0 | H16: =G16*1.2 -> 0
A17: 14 | E17: 0 | F17: 0 | G17: =E17*F17 -> 0 | H17: =G17*1.2 -> 0
... A43: 40 | E43: 0 | F43: 0 | G43: =E43*F43 -> 0 | H43: =G43*1.2 -> 0
A44: =A43+1 -> 41 | E44: 0 | F44: 0 | G44: =E44*F44 -> 0 | H44: =G44*1.2 -> 0
A45: =A44+1 -> 42 | E45: 0 | F45: 0 | G45: =E45*F45 -> 0 | H45: =G45*1.2 -> 0
A46: =A45+1 -> 43 | E46: 0 | F46: 0 | G46: =E46*F46 -> 0 | H46: =G46*1.2 -> 0
A47: =A46+1 -> 44 | E47: 0 | F47: 0 | G47: =E47*F47 -> 0 | H47: =G47*1.2 -> 0
A48: =A47+1 -> 45 | E48: 0 | F48: 0 | G48: =E48*F48 -> 0 | H48: =G48*1.2 -> 0
A49: =A48+1 -> 46 | E49: 0 | F49: 0 | G49: =E49*F49 -> 0 | H49: =G49*1.2 -> 0
A50: =A49+1 -> 47 | E50: 0 | F50: 0 | G50: =E50*F50 -> 0 | H50: =G50*1.2 -> 0
A51: =A50+1 -> 48 | E51: 0 | F51: 0 | G51: =E51*F51 -> 0 | H51: =G51*1.2 -> 0
A52: =A51+1 -> 49 | E52: 0 | F52: 0 | G52: =E52*F52 -> 0 | H52: =G52*1.2 -> 0
A53: =A52+1 -> 50 | E53: 0 | F53: 0 | G53: =E53*F53 -> 0 | H53: =G53*1.2 -> 0
A54: =A53+1 -> 51 | E54: 0 | F54: 0 | G54: =E54*F54 -> 0 | H54: =G54*1.2 -> 0
A55: =A54+1 -> 52 | E55: 0 | F55: 0 | G55: =E55*F55 -> 0 | H55: =G55*1.2 -> 0
... A83: =A82+1 -> 80 | E83: 0 | F83: 0 | G83: =E83*F83 -> 0 | H83: =G83*1.2 -> 0
A84: Общо разходи за оборудване | G84: =SUM(G4:G83) -> 44505 | H84: =SUM(H4:H83) -> 53406
B85: Част II: Планиран за закупуване софтуер
A86: 1 | B86: софтуер за управление на дигитално съдържание | C86: Създаване на програми и плейлисти Управление на списъци с програми и preview Връзка с всички терминали/екрани в мрежата, преглед на статуса им и съдържанието Създаване на разписания и графици Въвеждане на текстови съобщения | D86: х | E86: 6 | F86: 820 | G86: =E86*F86 -> 4920 | H86: =G86*1.2 -> 5904 | I86: Оферта 1 от 18.08.2023 и №6 31.07.23г.
A87: 2 | D87: х | E87: 0 | F87: 0 | G87: =E87*F87 -> 0 | H87: =G87*1.2 -> 0
A88: 3 | D88: х | E88: 0 | F88: 0 | G88: =E88*F88 -> 0 | H88: =G88*1.2 -> 0
A89: 4 | D89: х | E89: 0 | F89: 0 | G89: =E89*F89 -> 0 | H89: =G89*1.2 -> 0
A90: 5 | D90: х | E90: 0 | F90: 0 | G90: =E90*F90 -> 0 | H90: =G90*1.2 -> 0
A91: 6 | D91: х | E91: 0 | F91: 0 | G91: =E91*F91 -> 0 | H91: =G91*1.2 -> 0
A92: 7 | D92: х | E92: 0 | F92: 0 | G92: =E92*F92 -> 0 | H92: =G92*1.2 -> 0
...

Sheet Специализирано оборудване
A1: Остойностен списък със специализирано оборудване/софтуер
A2: № по ред | B2: Наименование на оборудване/софтуер/СМР | C2: Описание/Технически спецификации/характеристики | D2: Минимално ниво на оборудването по Направлението | E2: Количество | F2: Единична цена без ДДС (лева) | G2: Общо без ДДС (лева) | H2: Общо с ДДС (лева) | I2: Източник за формиране на единична цена на вид оборудване/софтуер/обзавеждане**
A3: Част I: Планирано за закупуване оборудване
A4: 1 | E4: 0 | F4: 0 | G4: =E4*F4 -> 0 | H4: =G4*1.2 -> 0
A5: 2 | E5: 0 | F5: 0 | G5: =E5*F5 -> 0 | H5: =G5*1.2 -> 0
A6: 3 | E6: 0 | F6: 0 | G6: =E6*F6 -> 0 | H6: =G6*1.2 -> 0
A7: 4 | E7: 0 | F7: 0 | G7: =E7*F7 -> 0 | H7: =G7*1.2 -> 0
A8: 5 | E8: 0 | F8: 0 | G8: =E8*F8 -> 0 | H8: =G8*1.2 -> 0
A9: 6 | E9: 0 | F9: 0 | G9: =E9*F9 -> 0 | H9: =G9*1.2 -> 0
A10: 7 | E10: 0 | F10: 0 | G10: =E10*F10 -> 0 | H10: =G10*1.2 -> 0
A11: 8 | E11: 0 | F11: 0 | G11: =E11*F11 -> 0 | H11: =G11*1.2 -> 0
A12: 9 | E12: 0 | F12: 0 | G12: =E12*F12 -> 0 | H12: =G12*1.2 -> 0
A13: 10 | E13: 0 | F13: 0 | G13: =E13*F13 -> 0 | H13: =G13*1.2 -> 0
A14: 11 | E14: 0 | F14: 0 | G14: =E14*F14 -> 0 | H14: =G14*1.2 -> 0
A15: 12 | E15: 0 | F15: 0 | G15: =E15*F15 -> 0 | H15: =G15*1.2 -> 0
... A83: 80 | E83: 0 | F83: 0 | G83: =E83*F83 -> 0 | H83: =G83*1.2 -> 0
A84: Общо разходи за оборудване | G84: =SUM(G4:G43) -> 0 | H84: =SUM(H4:H43) -> 0
B85: Част II: Планиран за закупуване софтуер
A86: 1 | D86: х | E86: 0 | F86: 0 | G86: =E86*F86 -> 0 | H86: =G86*1.2 -> 0
A87: 2 | D87: х | E87: 0 | F87: 0 | G87: =E87*F87 -> 0 | H87: =G87*1.2 -> 0
A88: 3 | D88: х | E88: 0 | F88: 0 | G88: =E88*F88 -> 0 | H88: =G88*1.2 -> 0
A89: 4 | D89: х | E89: 0 | F89: 0 | G89: =E89*F89 -> 0 | H89: =G89*1.2 -> 0
A90: 5 | D90: х | E90: 0 | F90: 0 | G90: =E90*F90 -> 0 | H90: =G90*1.2 -> 0
A91: 6 | D91: х | E91: 0 | F91: 0 | G91: =E91*F91 -> 0 | H91: =G91*1.2 -> 0
A92: 7 | D92: х | E92: 0 | F92: 0 | G92: =E92*F92 -> 0 | H92: =G92*1.2 -> 0
A93: 8 | D93: х | E93: 0 | F93: 0 | G93: =E93*F93 -> 0 | H93: =G93*1.2 -> 0
A94: 9 | D94: х | E94: 0 | F94: 0 | G94: =E94*F94 -> 0 | H94: =G94*1.2 -> 0
A95: 10 | D95: х | E95: 0 | F95: 0 | G95: =E95*F95 -> 0 | H95: =G95*1.2 -> 0
A96: 11 | D96: х | E96: 0 | F96: 0 | G96: =E96*F96 -> 0 | H96: =G96*1.2 -> 0
A97: 12 | D97: х | E97: 0 | F97: 0 | G97: =E97*F97 -> 0 | H97: =G97*1.2 -> 0
... A125: 40 | D125: х | E125: 0 | F125: 0 | G125: =E125*F125 -> 0 | H125: =G125*1.2 -> 0
A126: Общо разходи за софтуер | G126: =SUM(G86:G105) -> 0 | H126: =SUM(H86:H105) -> 0
A127: Общо разходи за оборудване/софтуер | G127: =G84+G126 -> 0 | H127: =H84+H126 -> 0
A128: ** В колона "Източник за формиране на единична цена на вид оборудване/софтуер" се посочват подходящи източници на информация, въз основа на които са определени планираните стойности на разходите - проучвания в интернет (хиперлинкове към съответните интернет базирани източници) и/или номер и дата на оферта/и.

Sheet Училища
A1: Код по НЕИСПУО | B1: Област | C1: Община | D1: Населено място | E1: Пълно наименование на институция | F1: Детайлен вид на институция | G1: Вид на институцията според финансирането | H1: Учебна 2020/2021 година | I1: Учебна 2021/2022 година | J1: Учебна 2022/2023 година | K1: Средноаритметичен брой ученици за учебните 2020/2021, 2021/2022 и 2022/2023 учебна година | L1: Средства STEM в лв. с ДДС | M1: в това число максимален размер на разходите за СМР и обзавеждане за STEM (до 45 % от средствата за STEM) в лв. с ДДС | N1: в това число минимален размер на разходите за оборудване за STEM (минимум 45 % от средствата за STEM) в лв. с ДДС | O1: в това число максимален размер на разходите за допълнително специализирано оборудване за STEM (до 20 % от разходите за оборудване за STEM) в лв. с ДДС | P1: в това число максимален размер на разходите за софтуер за STEM (до 10 % от средствата за STEM) в лв. с ДДС | Q1: Средства ВОСКС в лв. с ДДС | R1: Минимален брой оборудвани ВОСКС | S1: в това число максимален размер на разходите за софтуер за ВОСКС (до 10 % от средствата за ВОСКС) в лв. с ДДС | T1: Общо средства (STEM и ВОСКС) в лв. с ДДС | U1: Средства за организация и управление (1%) от средствата за STEM и ВОСКС в лв. с ДДС | V1: Общо средства за изграждане на училищна STEM среда в лв. с ДДС | W1: Булстат/ЕИК
A2: 1702623 | B2: Разград | C2: Разград | D2: Киченица | E2: Основно училище "Кирил и Методий" | F2: основно | G2: Общинско | H2: 39 | I2: 36 | J2: 15 | K2: =+(H2+I2+J2)/3 -> 30 | L2: 0 | M2: =+L2*0.45 -> 0 | N2: =+L2*0.45 -> 0 | O2: =+N2*0.2 -> 0 | P2: =++L2*0.1 -> 0 | Q2: 0 | R2: 0 | S2: =+Q2*0.1 -> 0 | T2: =+L2+Q2 -> 0 | U2: =+T2*0.01 -> 0 | V2: =+T2+U2 -> 0 | W2: 000498800
A3: 1900516 | B3: Силистра | C3: Силистра | D3: Брадвари | E3: Основно училище "Св. св. Кирил и Методий" | F3: основно | G3: Общинско | H3: 50 | I3: 39 | J3: 35 | K3: =+(H3+I3+J3)/3 -> 41.333333 | L3: 0 | M3: =+L3*0.45 -> 0 | N3: =+L3*0.45 -> 0 | O3: =+N3*0.2 -> 0 | P3: =++L3*0.1 -> 0 | Q3: 0 | R3: 0 | S3: =+Q3*0.1 -> 0 | T3: =+L3+Q3 -> 0 | U3: =+T3*0.01 -> 0 | V3: =+T3+U3 -> 0 | W3: 000558667
A4: 100020 | B4: Благоевград | C4: Благоевград | D4: Благоевград | E4: Второ основно училище "Димитър Благоев" | F4: основно | G4: Общинско | H4: 528 | I4: 531 | J4: 533 | K4: =+(H4+I4+J4)/3 -> 530.66667 | L4: =300000*0.7 -> 210000 | M4: =+L4*0.45 -> 94500 | N4: =+L4*0.45 -> 94500 | O4: =+N4*0.2 -> 18900 | P4: =++L4*0.1 -> 21000 | Q4: 60000 | R4: 6 | S4: =+Q4*0.1 -> 6000 | T4: =+L4+Q4 -> 270000 | U4: =+T4*0.01 -> 2700 | V4: =+T4+U4 -> 272700 | W4: 000012465
A5: 100040 | B5: Благоевград | C5: Благоевград | D5: Благоевград | E5: Четвърто основно училище " Димчо Дебелянов" | F5: основно | G5: Общинско | H5: 261 | I5: 271 | J5: 281 | K5: =+(H5+I5+J5)/3 -> 271 | L5: 200000 | M5: =+L5*0.45 -> 90000 | N5: =+L5*0.45 -> 90000 | O5: =+N5*0.2 -> 18000 | P5: =++L5*0.1 -> 20000 | Q5: 50000 | R5: 5 | S5: =+Q5*0.1 -> 5000 | T5: =+L5+Q5 -> 250000 | U5: =+T5*0.01 -> 2500 | V5: =+T5+U5 -> 252500 | W5: 000012487
A6: 100052 | B6: Благоевград | C6: Благоевград | D6: Благоевград | E6: Благоевградска професионална гимназия "Ичко Бойчев" | F6: професионална гимназия | G6: Общинско | H6: 253 | I6: 280 | J6: 298 | K6: =+(H6+I6+J6)/3 -> 277 | L6: 200000 | M6: =+L6*0.45 -> 90000 | N6: =+L6*0.45 -> 90000 | O6: =+N6*0.2 -> 18000 | P6: =++L6*0.1 -> 20000 | Q6: 50000 | R6: 5 | S6: =+Q6*0.1 -> 5000 | T6: =+L6+Q6 -> 250000 | U6: =+T6*0.01 -> 2500 | V6: =+T6+U6 -> 252500 | W6: 000017003
A7: 100070 | B7: Благоевград | C7: Благоевград | D7: Благоевград | E7: Седмо средно училище "Кузман Шапкарев" | F7: средно | G7: Общинско | H7: 888 | I7: 923 | J7: 923 | K7: =+(H7+I7+J7)/3 -> 911.33333 | L7: =300000*0.7 -> 210000 | M7: =+L7*0.45 -> 94500 | N7: =+L7*0.45 -> 94500 | O7: =+N7*0.2 -> 18900 | P7: =++L7*0.1 -> 21000 | Q7: 60000 | R7: 6 | S7: =+Q7*0.1 -> 6000 | T7: =+L7+Q7 -> 270000 | U7: =+T7*0.01 -> 2700 | V7: =+T7+U7 -> 272700 | W7: 000016976
A8: 100110 | B8: Благоевград | C8: Благоевград | D8: Благоевград | E8: Единадесето основно училище "Христо Ботев" | F8: основно | G8: Общинско | H8: 364 | I8: 385 | J8: 401 | K8: =+(H8+I8+J8)/3 -> 383.33333 | L8: 200000 | M8: =+L8*0.45 -> 90000 | N8: =+L8*0.45 -> 90000 | O8: =+N8*0.2 -> 18000 | P8: =++L8*0.1 -> 20000 | Q8: 50000 | R8: 5 | S8: =+Q8*0.1 -> 5000 | T8: =+L8+Q8 -> 250000 | U8: =+T8*0.01 -> 2500 | V8: =+T8+U8 -> 252500 | W8: 000019399
A9: 100190 | B9: Благоевград | C9: Благоевград | D9: Благоевград | E9: Езикова гимназия "Акад. Людмил Стоянов" | F9: профилирана гимназия | G9: Общинско | H9: 795 | I9: 793 | J9: 795 | K9: =+(H9+I9+J9)/3 -> 794.33333 | L9: =300000 -> 300000 | M9: =+L9*0.45 -> 135000 | N9: =+L9*0.45 -> 135000 | O9: =+N9*0.2 -> 27000 | P9: =++L9*0.1 -> 30000 | Q9: 60000 | R9: 6 | S9: =+Q9*0.1 -> 6000 | T9: =+L9+Q9 -> 360000 | U9: =+T9*0.01 -> 3600 | V9: =+T9+U9 -> 363600 | W9: 000019100
A10: 100200 | B10: Благоевград | C10: Благоевград | D10: Благоевград | E10: Природо-математическа гимназия "Акад. Сергей Корольов" | F10: профилирана гимназия | G10: Общинско | H10: 868 | I10: 866 | J10: 863 | K10: =+(H10+I10+J10)/3 -> 865.66667 | L10: =300000 -> 300000 | M10: =+L10*0.45 -> 135000 | N10: =+L10*0.45 -> 135000 | O10: =+N10*0.2 -> 27000 | P10: =++L10*0.1 -> 30000 | Q10: 60000 | R10: 6 | S10: =+Q10*0.1 -> 6000 | T10: =+L10+Q10 -> 360000 | U10: =+T10*0.01 -> 3600 | V10: =+T10+U10 -> 363600 | W10: 000016983
A11: 100280 | B11: Благоевград | C11: Благоевград | D11: Благоевград | E11: Професионална гимназия по икономика "Иван Илиев" | F11: професионална гимназия | G11: Държавно | H11: 545 | I11: 520 | J11: 518 | K11: =+(H11+I11+J11)/3 -> 527.66667 | L11: =300000 -> 300000 | M11: =+L11*0.45 -> 135000 | N11: =+L11*0.45 -> 135000 | O11: =+N11*0.2 -> 27000 | P11: =++L11*0.1 -> 30000 | Q11: 60000 | R11: 6 | S11: =+Q11*0.1 -> 6000 | T11: =+L11+Q11 -> 360000 | U11: =+T11*0.01 -> 3600 | V11: =+T11+U11 -> 363600 | W11: 000014060
A12: 100300 | B12: Благоевград | C12: Благоевград | D12: Благоевград | E12: Професионална гимназия по строителство, архитектура и геодезия " Васил Левски" | F12: професионална гимназия | G12: Държавно | H12: 389 | I12: 378 | J12: 401 | K12: =+(H12+I12+J12)/3 -> 389.33333 | L12: 200000 | M12: =+L12*0.45 -> 90000 | N12: =+L12*0.45 -> 90000 | O12: =+N12*0.2 -> 18000 | P12: =++L12*0.1 -> 20000 | Q12: 50000 | R12: 5 | S12: =+Q12*0.1 -> 5000 | T12: =+L12+Q12 -> 250000 | U12: =+T12*0.01 -> 2500 | V12: =+T12+U12 -> 252500 | W12: 000014078
A13: 101250 | B13: Благоевград | C13: Благоевград | D13: Благоевград | E13: Средно училище с изучаване на чужди езици "Свети Климент Охридски" | F13: средно | G13: Общинско | H13: 505 | I13: 469 | J13: 459 | K13: =+(H13+I13+J13)/3 -> 477.66667 | L13: =300000 -> 300000 | M13: =+L13*0.45 -> 135000 | N13: =+L13*0.45 -> 135000 | O13: =+N13*0.2 -> 27000 | P13: =++L13*0.1 -> 30000 | Q13: 60000 | R13: 6 | S13: =+Q13*0.1 -> 6000 | T13: =+L13+Q13 -> 360000 | U13: =+T13*0.01 -> 3600 | V13: =+T13+U13 -> 363600 | W13: 000019456
A14: 101290 | B14: Благоевград | C14: Благоевград | D14: Благоевград | E14: Трето основно училище "Димитър Талев" | F14: основно | G14: Общинско | H14: 782 | I14: 741 | J14: 695 | K14: =+(H14+I14+J14)/3 -> 739.33333 | L14: =300000 -> 300000 | M14: =+L14*0.45 -> 135000 | N14: =+L14*0.45 -> 135000 | O14: =+N14*0.2 -> 27000 | P14: =++L14*0.1 -> 30000 | Q14: 60000 | R14: 6 | S14: =+Q14*0.1 -> 6000 | T14: =+L14+Q14 -> 360000 | U14: =+T14*0.01 -> 3600 | V14: =+T14+U14 -> 363600 | W14: 000012472
A15: 101301 | B15: Благоевград | C15: Гърмен | D15: Гърмен | E15: Средно училище "Св.Св.Кирил и Методий" | F15: средно | G15: Общинско | H15: 348 | I15: 333 | J15: 319 | K15: =+(H15+I15+J15)/3 -> 333.33333 | L15: 200000 | M15: =+L15*0.45 -> 90000 | N15: =+L15*0.45 -> 90000 | O15: =+N15*0.2 -> 18000 | P15: =++L15*0.1 -> 20000 | Q15: 50000 | R15: 5 | S15: =+Q15*0.1 -> 5000 | T15: =+L15+Q15 -> 250000 | U15: =+T15*0.01 -> 2500 | V15: =+T15+U15 -> 252500 | W15: 000012942
A16: 101580 | B16: Благоевград | C16: Благоевград | D16: Благоевград | E16: Осмо средно училище "Арсени Костенцев" | F16: средно | G16: Общинско | H16: 716 | I16: 685 | J16: 676 | K16: =+(H16+I16+J16)/3 -> 692.33333 | L16: =300000 -> 300000 | M16: =+L16*0.45 -> 135000 | N16: =+L16*0.45 -> 135000 | O16: =+N16*0.2 -> 27000 | P16: =++L16*0.1 -> 30000 | Q16: 60000 | R16: 6 | S16: =+Q16*0.1 -> 6000 | T16: =+L16+Q16 -> 360000 | U16: =+T16*0.01 -> 3600 | V16: =+T16+U16 -> 363600 | W16: 000019050
A17: 101700 | B17: Благоевград | C17: Благоевград | D17: Благоевград | E17: Девето основно училище " Пейо Крачолов Яворов" | F17: основно | G17: Общинско | H17: 111 | I17: 105 | J17: 117 | K17: =+(H17+I17+J17)/3 -> 111 | L17: 150000 | M17: =+L17*0.45 -> 67500 | N17: =+L17*0.45 -> 67500 | O17: =+N17*0.2 -> 13500 | P17: =++L17*0.1 -> 15000 | Q17: 30000 | R17: 3 | S17: =+Q17*0.1 -> 3000 | T17: =+L17+Q17 -> 180000 | U17: =+T17*0.01 -> 1800 | V17: =+T17+U17 -> 181800 | W17: 000019189
A18: 101730 | B18: Благоевград | C18: Благоевград | D18: Благоевград | E18: Професионална гимназия по туризъм и лека промишленост "Гоце Делчев" | F18: професионална гимназия | G18: Общинско | H18: 200 | I18: 212 | J18: 230 | K18: =+(H18+I18+J18)/3 -> 214 | L18: 200000 | M18: =+L18*0.45 -> 90000 | N18: =+L18*0.45 -> 90000 | O18: =+N18*0.2 -> 18000 | P18: =++L18*0.1 -> 20000 | Q18: 50000 | R18: 5 | S18: =+Q18*0.1 -> 5000 | T18: =+L18+Q18 -> 250000 | U18: =+T18*0.01 -> 2500 | V18: =+T18+U18 -> 252500 | W18: 101074104
A19: 101820 | B19: Благоевград | C19: Благоевград | D19: Благоевград | E19: Център за специална образователна подкрепа "Свети Паисий Хилендарски" | F19: център за специална образователна подкрепа | G19: Държавно | H19: 109 | I19: 121 | J19: 121 | K19: =+(H19+I19+J19)/3 -> 117 | L19: 150000 | M19: =+L19*0.45 -> 67500 | N19: =+L19*0.45 -> 67500 | O19: =+N19*0.2 -> 13500 | P19: =++L19*0.1 -> 15000 | Q19: 30000 | R19: 3 | S19: =+Q19*0.1 -> 3000 | T19: =+L19+Q19 -> 180000 | U19: =+T19*0.01 -> 1800 | V19: =+T19+U19 -> 181800 | W19: 000014014
A20: 101870 | B20: Благоевград | C20: Благоевград | D20: Благоевград | E20: Национална хуманитарна гимназия"Св.св.Кирил и Методий" | F20: профилирана гимназия | G20: Общинско | H20: 620 | I20: 648 | J20: 666 | K20: =+(H20+I20+J20)/3 -> 644.66667 | L20: =300000 -> 300000 | M20: =+L20*0.45 -> 135000 | N20: =+L20*0.45 -> 135000 | O20: =+N20*0.2 -> 27000 | P20: =++L20*0.1 -> 30000 | Q20: 60000 | R20: 6 | S20: =+Q20*0.1 -> 6000 | T20: =+L20+Q20 -> 360000 | U20: =+T20*0.01 -> 3600 | V20: =+T20+U20 -> 363600 | W20: 000013916
A21: 101880 | B21: Благоевград | C21: Благоевград | D21: Благоевград | E21: Средно училище "Иван Вазов" | F21: средно | G21: Общинско | H21: 445 | I21: 452 | J21: 467 | K21: =+(H21+I21+J21)/3 -> 454.66667 | L21: =300000 -> 300000 | M21: =+L21*0.45 -> 135000 | N21: =+L21*0.45 -> 135000 | O21: =+N21*0.2 -> 27000 | P21: =++L21*0.1 -> 30000 | Q21: 60000 | R21: 6 | S21: =+Q21*0.1 -> 6000 | T21: =+L21+Q21 -> 360000 | U21: =+T21*0.01 -> 3600 | V21: =+T21+U21 -> 363600 | W21: 000012700
A22: 102001 | B22: Благоевград | C22: Гоце Делчев | D22: Гоце Делчев | E22: Неврокопска професионална гимназия "Димитър Талев" | F22: професионална гимназия | G22: Държавно | H22: 711 | I22: 770 | J22: 817 | K22: =+(H22+I22+J22)/3 -> 766 | L22: =300000 -> 300000 | M22: =+L22*0.45 -> 135000 | N22: =+L22*0.45 -> 135000 | O22: =+N22*0.2 -> 27000 | P22: =++L22*0.1 -> 30000 | Q22: 60000 | R22: 6 | S22: =+Q22*0.1 -> 6000 | T22: =+L22+Q22 -> 360000 | U22: =+T22*0.01 -> 3600 | V22: =+T22+U22 -> 363600 | W22: 000014249
A23: 102002 | B23: Благоевград | C23: Гоце Делчев | D23: Гоце Делчев | E23: Природо-математическа гимназия "Яне Сандански" | F23: профилирана гимназия | G23: Общинско | H23: 703 | I23: 717 | J23: 703 | K23: =+(H23+I23+J23)/3 -> 707.66667 | L23: =300000 -> 300000 | M23: =+L23*0.45 -> 135000 | N23: =+L23*0.45 -> 135000 | O23: =+N23*0.2 -> 27000 | P23: =++L23*0.1 -> 30000 | Q23: 60000 | R23: 6 | S23: =+Q23*0.1 -> 6000 | T23: =+L23+Q23 -> 360000 | U23: =+T23*0.01 -> 3600 | V23: =+T23+U23 -> 363600 | W23: 000013923
A24: 102003 | B24: Благоевград | C24: Банско | D24: Места | E24: Основно училище "Свети свети Кирил и Методий" | F24: основно | G24: Общинско | H24: 51 | I24: 51 | J24: 48 | K24: =+(H24+I24+J24)/3 -> 50 | L24: 50000 | M24: =+L24*0.45 -> 22500 | N24: =+L24*0.45 -> 22500 | O24: =+N24*0.2 -> 4500 | P24: =++L24*0.1 -> 5000 | Q24: 10000 | R24: 1 | S24: =+Q24*0.1 -> 1000 | T24: =+L24+Q24 -> 60000 | U24: =+T24*0.01 -> 600 | V24: =+T24+U24 -> 60600 | W24: 000013081
A25: 102004 | B25: Благоевград | C25: Банско | D25: Банско | E25: Професионална лесотехническа гимназия"Никола Йонков Вапцаров" | F25: професионална гимназия | G25: Общинско | H25: 193 | I25: 171 | J25: 159 | K25: =+(H25+I25+J25)/3 -> 174.33333 | L25: =150000*0.7 -> 105000 | M25: =+L25*0.45 -> 47250 | N25: =+L25*0.45 -> 47250 | O25: =+N25*0.2 -> 9450 | P25: =++L25*0.1 -> 10500 | Q25: 30000 | R25: 3 | S25: =+Q25*0.1 -> 3000 | T25: =+L25+Q25 -> 135000 | U25: =+T25*0.01 -> 1350 | V25: =+T25+U25 -> 136350 | W25: 000014103
A26: 102007 | B26: Благоевград | C26: Сандански | D26: Сандански | E26: Професионална техническа гимназия | F26: професионална гимназия | G26: Държавно | H26: 117 | I26: 118 | J26: 136 | K26: =+(H26+I26+J26)/3 -> 123.66667 | L26: 150000 | M26: =+L26*0.45 -> 67500 | N26: =+L26*0.45 -> 67500 | O26: =+N26*0.2 -> 13500 | P26: =++L26*0.1 -> 15000 | Q26: 30000 | R26: 3 | S26: =+Q26*0.1 -> 3000 | T26: =+L26+Q26 -> 180000 | U26: =+T26*0.01 -> 1800 | V26: =+T26+U26 -> 181800 | W26: 000017163
A27: 102009 | B27: Благоевград | C27: Петрич | D27: Петрич | E27: Професионална гимназия по механоелектротехника "Юрий Гагарин" | F27: професионална гимназия | G27: Държавно | H27: 273 | I27: 283 | J27: 270 | K27: =+(H27+I27+J27)/3 -> 275.33333 | L27: 200000 | M27: =+L27*0.45 -> 90000 | N27: =+L27*0.45 -> 90000 | O27: =+N27*0.2 -> 18000 | P27: =++L27*0.1 -> 20000 | Q27: 50000 | R27: 5 | S27: =+Q27*0.1 -> 5000 | T27: =+L27+Q27 -> 250000 | U27: =+T27*0.01 -> 2500 | V27: =+T27+U27 -> 252500 | W27: 000014231
A28: 102010 | B28: Благоевград | C28: Банско | D28: Банско | E28: Гимназия по туризъм "Алеко Константинов" | F28: професионална гимназия | G28: Общинско | H28: 79 | I28: 99 | J28: 98 | K28: =+(H28+I28+J28)/3 -> 92 | L28: 150000 | M28: =+L28*0.45 -> 67500 | N28: =+L28*0.45 -> 67500 | O28: =+N28*0.2 -> 13500 | P28: =++L28*0.1 -> 15000 | Q28: 30000 | R28: 3 | S28: =+Q28*0.1 -> 3000 | T28: =+L28+Q28 -> 180000 | U28: =+T28*0.01 -> 1800 | V28: =+T28+U28 -> 181800 | W28: 000014306
A29: 102011 | B29: Благоевград | C29: Якоруда | D29: Якоруда | E29: Професионална гимназия "Петко Рачов Славейков" | F29: професионална гимназия | G29: Държавно | H29: 165 | I29: 171 | J29: 180 | K29: =+(H29+I29+J29)/3 -> 172 | L29: 150000 | M29: =+L29*0.45 -> 67500 | N29: =+L29*0.45 -> 67500 | O29: =+N29*0.2 -> 13500 | P29: =++L29*0.1 -> 15000 | Q29: 30000 | R29: 3 | S29: =+Q29*0.1 -> 3000 | T29: =+L29+Q29 -> 180000 | U29: =+T29*0.01 -> 1800 | V29: =+T29+U29 -> 181800 | W29: 000014150
A30: 102012 | B30: Благоевград | C30: Разлог | D30: Разлог | E30: Разложка професионална гимназия "Никола Стойчев" | F30: професионална гимназия | G30: Държавно | H30: 224 | I30: 202 | J30: 203 | K30: =+(H30+I30+J30)/3 -> 209.66667 | L30: 200000 | M30: =+L30*0.45 -> 90000 | N30: =+L30*0.45 -> 90000 | O30: =+N30*0.2 -> 18000 | P30: =++L30*0.1 -> 20000 | Q30: 50000 | R30: 5 | S30: =+Q30*0.1 -> 5000 | T30: =+L30+Q30 -> 250000 | U30: =+T30*0.01 -> 2500 | V30: =+T30+U30 -> 252500 | W30: 000014199
A31: 102013 | B31: Благоевград | C31: Сандански | D31: Сандански | E31: Земеделска професионална гимназия "Климент Аркадиевич Тимирязев" | F31: професионална гимназия | G31: Общинско | H31: 731 | I31: 750 | J31: 760 | K31: =+(H31+I31+J31)/3 -> 747 | L31: =300000*0.7 -> 210000 | M31: =+L31*0.45 -> 94500 | N31: =+L31*0.45 -> 94500 | O31: =+N31*0.2 -> 18900 | P31: =++L31*0.1 -> 21000 | Q31: 60000 | R31: 6 | S31: =+Q31*0.1 -> 6000 | T31: =+L31+Q31 -> 270000 | U31: =+T31*0.01 -> 2700 | V31: =+T31+U31 -> 272700 | W31: 000014128
A32: 102014 | B32: Благоевград | C32: Петрич | D32: Петрич | E32: Професионална гимназия по икономика и туризъм " Проф. д-р Асен Златаров" | F32: професионална гимназия | G32: Държавно | H32: 527 | I32: 530 | J32: 504 | K32: =+(H32+I32+J32)/3 -> 520.33333 | L32: =300000 -> 300000 | M32: =+L32*0.45 -> 135000 | N32: =+L32*0.45 -> 135000 | O32: =+N32*0.2 -> 27000 | P32: =++L32*0.1 -> 30000 | Q32: 60000 | R32: 6 | S32: =+Q32*0.1 -> 6000 | T32: =+L32+Q32 -> 360000 | U32: =+T32*0.01 -> 3600 | V32: =+T32+U32 -> 363600 | W32: 101043817
A33: 102015 | B33: Благоевград | C33: Банско | D33: Банско | E33: Професионална гимназия по електроника и енергетика | F33: професионална гимназия | G33: Държавно | H33: 217 | I33: 223 | J33: 249 | K33: =+(H33+I33+J33)/3 -> 229.66667 | L33: 200000 | M33: =+L33*0.45 -> 90000 | N33: =+L33*0.45 -> 90000 | O33: =+N33*0.2 -> 18000 | P33: =++L33*0.1 -> 20000 | Q33: 50000 | R33: 5 | S33: =+Q33*0.1 -> 5000 | T33: =+L33+Q33 -> 250000 | U33: =+T33*0.01 -> 2500 | V33: =+T33+U33 -> 252500 | W33: 000014110
A34: 102016 | B34: Благоевград | C34: Гоце Делчев | D34: Гоце Делчев | E34: Професионална гимназия по механизация на селското стопанство "Пейо Крачолов Яворов" | F34: професионална гимназия | G34: Общинско | H34: 440 | I34: 442 | J34: 490 | K34: =+(H34+I34+J34)/3 -> 457.33333 | L34: =300000*0.7 -> 210000 | M34: =+L34*0.45 -> 94500 | N34: =+L34*0.45 -> 94500 | O34: =+N34*0.2 -> 18900 | P34: =++L34*0.1 -> 21000 | Q34: 60000 | R34: 6 | S34: =+Q34*0.1 -> 6000 | T34: =+L34+Q34 -> 270000 | U34: =+T34*0.01 -> 2700 | V34: =+T34+U34 -> 272700 | W34: 000014313
A35: 102017 | B35: Благоевград | C35: Разлог | D35: Разлог | E35: Професионална гимназия по механизация на селското стопанствo | F35: професионална гимназия | G35: Общинско | H35: 241 | I35: 258 | J35: 304 | K35: =+(H35+I35+J35)/3 -> 267.66667 | L35: 200000 | M35: =+L35*0.45 -> 90000 | N35: =+L35*0.45 -> 90000 | O35: =+N35*0.2 -> 18000 | P35: =++L35*0.1 -> 20000 | Q35: 50000 | R35: 5 | S35: =+Q35*0.1 -> 5000 | T35: =+L35+Q35 -> 250000 | U35: =+T35*0.01 -> 2500 | V35: =+T35+U35 -> 252500 | W35: 000014320
A36: 102060 | B36: Благоевград | C36: Благоевград | D36: Благоевград | E36: Пето средно училище "Георги Измирлиев" | F36: средно | G36: Общинско | H36: 436 | I36: 463 | J36: 490 | K36: =+(H36+I36+J36)/3 -> 463 | L36: =300000 -> 300000 | M36: =+L36*0.45 -> 135000 | N36: =+L36*0.45 -> 135000 | O36: =+N36*0.2 -> 27000 | P36: =++L36*0.1 -> 30000 | Q36: 60000 | R36: 6 | S36: =+Q36*0.1 -> 6000 | T36: =+L36+Q36 -> 360000 | U36: =+T36*0.01 -> 3600 | V36: =+T36+U36 -> 363600 | W36: 000012497
A37: 102113 | B37: Благоевград | C37: Разлог | D37: Разлог | E37: Професионална гимназия по транспорт | F37: професионална гимназия | G37: Държавно | H37: 303 | I37: 314 | J37: 307 | K37: =+(H37+I37+J37)/3 -> 308 | L37: 200000 | M37: =+L37*0.45 -> 90000 | N37: =+L37*0.45 -> 90000 | O37: =+N37*0.2 -> 18000 | P37: =++L37*0.1 -> 20000 | Q37: 50000 | R37: 5 | S37: =+Q37*0.1 -> 5000 | T37: =+L37+Q37 -> 250000 | U37: =+T37*0.01 -> 2500 | V37: =+T37+U37 -> 252500 | W37: 000016855
A38: 102606 | B38: Благоевград | C38: Сандански | D38: Сандански | E38: Второ основно училище "Христо Смирненски" | F38: основно | G38: Общинско | H38: 575 | I38: 596 | J38: 625 | K38: =+(H38+I38+J38)/3 -> 598.66667 | L38: =300000 -> 300000 | M38: =+L38*0.45 -> 135000 | N38: =+L38*0.45 -> 135000 | O38: =+N38*0.2 -> 27000 | P38: =++L38*0.1 -> 30000 | Q38: 60000 | R38: 6 | S38: =+Q38*0.1 -> 6000 | T38: =+L38+Q38 -> 360000 | U38: =+T38*0.01 -> 3600 | V38: =+T38+U38 -> 363600 | W38: 000012604
A39: 103002 | B39: Благоевград | C39: Гърмен | D39: Рибново | E39: Средно училище "Йордан Йовков" | F39: средно | G39: Общинско | H39: 552 | I39: 550 | J39: 574 | K39: =+(H39+I39+J39)/3 -> 558.66667 | L39: =300000 -> 300000 | M39: =+L39*0.45 -> 135000 | N39: =+L39*0.45 -> 135000 | O39: =+N39*0.2 -> 27000 | P39: =++L39*0.1 -> 30000 | Q39: 60000 | R39: 6 | S39: =+Q39*0.1 -> 6000 | T39: =+L39+Q39 -> 360000 | U39: =+T39*0.01 -> 3600 | V39: =+T39+U39 -> 363600 | W39: 000013115
A40: 103004 | B40: Благоевград | C40: Гърмен | D40: Огняново | E40: Основно училище "Пейо Крачолов Яворов" | F40: основно | G40: Общинско | H40: 127 | I40: 135 | J40: 126 | K40: =+(H40+I40+J40)/3 -> 129.33333 | L40: 150000 | M40: =+L40*0.45 -> 67500 | N40: =+L40*0.45 -> 67500 | O40: =+N40*0.2 -> 13500 | P40: =++L40*0.1 -> 15000 | Q40: 30000 | R40: 3 | S40: =+Q40*0.1 -> 3000 | T40: =+L40+Q40 -> 180000 | U40: =+T40*0.01 -> 1800 | V40: =+T40+U40 -> 181800 | W40: 000013097
...

Sheet Стойности
A1: Училището Ви има ли изграден STEM център към момента на кандидатстване
B2: 1 - Да, 2 - Не
A3: 1.1 | B3: 2
A4: В кой/кои образователни етапи ще се използва центърът
B5: Начален | C5: Гимназиален | D5: Прогимназиален
